{"_id":"d631495c-5c19-3a9b-a477-a5fec598ae4a","authorName":"Stephen Cleary","authorEmailEncrypted":"","authorEmailMD5":"3db7b6e14d9da42751e4bab03bc4d034","authorUri":"https://stephencleary.com/","authorUserId":"","authorFallbackAvatar":"","message":"No; the comments are correct. The async keyword establishes the state machine, which catches the exception and places it on the returned task, so the exception is thrown when the task is await'ed. Without the async keyword, there's no state machine, so the exception is thrown immediately when the method is called.","postId":"2016_12_eliding-async-await-98a72933-845d-3c59-9bd5-b4160554a9f7","replyTo":"10228738-52fd-3bc3-a9f6-10b239a034e3","date":"2017-12-11T00:30:02Z","timestamp":1512952202}