{"_id":"fe0ae403-758d-3ae0-8ab4-10c73fe47a28","authorName":"Stephen Cleary","authorEmailEncrypted":"U22AzyvtKygG/mOvXfImfPwuxrcVS5vlOSkFrnl8vLBRaag0Lr/fLhkgGQFImlh1Zds7qbL/ilXc90Ozo8588b3HAPB3veeitZaw08vNfKFQVYfL+6Cg6jxOFvkZIiGdeJA7HVCyDGgqksYtH4SisdDQ7Qio7sYF/ctTixlOmpXseXhduaZmmg1uUfdQRsj04tUHC3F9LoCBN78oefORYFxAYtHQqKaAUYJPf89UpeQXsasqn3FJ47pPsvJe5eppmz0mFCtFpSUqP6ZRvDjrwgi2re9xR+tNczbL9UeebsLUOoA6C/H+paQwnVNevQZHSBdvHnovLQNkFQ3JxFrFZeS8z3DaFrVM9Q+JJJGeD79017cPCT2CRCtRgNLBvOEXCEHf7BRK5sGmrTeOFoE164nljfggfummIRmwK9gsFN3iSA2QsNIQAYJOncJ4OUdWawyBrIfeUYWsf38A5BRGE2PvE5mR/+SvG7dnjL+og5b1RBoq6QaWIn5IwRqxOp7fELwjXQr/XtLVDklaOyrUZbYKWSEA3rM4Mx4yxpizPV3xV3ss3pBLpoUf3sGdrkVJxvQ0K8gQllFyAssNnaBfy50on9gHUaiV4GWiIL/NGxYRMcCheGkIeay/pi4N96y1/5lPV0SlXdJbrmx0Ma2pFNQbshCc//Ci9dj36cWsWrU=","authorEmailMD5":"ad2250182ff26a84dda974e50cd94382","message":"Yes, you are correct. Sorry, I read through that code too quickly and missed that. If the try/catch is inside the Task.Run, then it will be on a thread pool thread. You can move the try/catch to be outside the Task.Run, and then it will be on the UI thread:\r\n\r\nprivate async Task MethodThatReturnsATask()  \r\n{  \r\ntry  \r\n{  \r\nawait Task.Run(() =>  \r\n{  \r\n// fetch data from service  \r\n});  \r\n}  \r\ncatch (Exception e)  \r\n{  \r\nstring err = \"Cannot get data\";  \r\nLogger.Error(err, e);  \r\n_dialogService.ShowError(e);  \r\n}  \r\n}","postId":"2014_04_announcement-msdn-async-mvvm-articles-b2165e1d-7e99-386d-b481-ed64583f3ab7","replyTo":"b71979cc-5d4b-357e-8bbc-7b9aab65ff31","date":"2017-03-13T13:08:35Z","timestamp":1489410515,"authorUserId":"disqus:stephen_cleary"}